[2023-05-09T12:19:17.008+0000] {taskinstance.py:1125} INFO - Dependencies all met for dep_context=non-requeueable deps ti=<TaskInstance: question1.create_table scheduled__2022-12-20T00:00:00+00:00 [queued]>
[2023-05-09T12:19:17.018+0000] {taskinstance.py:1125} INFO - Dependencies all met for dep_context=requeueable deps ti=<TaskInstance: question1.create_table scheduled__2022-12-20T00:00:00+00:00 [queued]>
[2023-05-09T12:19:17.019+0000] {taskinstance.py:1331} INFO - Starting attempt 1 of 1
[2023-05-09T12:19:17.057+0000] {taskinstance.py:1350} INFO - Executing <Task(PostgresOperator): create_table> on 2022-12-20 00:00:00+00:00
[2023-05-09T12:19:17.066+0000] {standard_task_runner.py:57} INFO - Started process 1079 to run task
[2023-05-09T12:19:17.089+0000] {standard_task_runner.py:84} INFO - Running: ['***', 'tasks', 'run', 'question1', 'create_table', 'scheduled__2022-12-20T00:00:00+00:00', '--job-id', '357', '--raw', '--subdir', 'DAGS_FOLDER/dag1.py', '--cfg-path', '/tmp/tmpakyy43d1']
[2023-05-09T12:19:17.090+0000] {standard_task_runner.py:85} INFO - Job 357: Subtask create_table
[2023-05-09T12:19:17.165+0000] {task_command.py:410} INFO - Running <TaskInstance: question1.create_table scheduled__2022-12-20T00:00:00+00:00 [running]> on host f3950ac719e7
[2023-05-09T12:19:17.267+0000] {taskinstance.py:1570} INFO - Exporting env vars: AIRFLOW_CTX_DAG_OWNER='***' AIRFLOW_CTX_DAG_ID='question1' AIRFLOW_CTX_TASK_ID='create_table' AIRFLOW_CTX_EXECUTION_DATE='2022-12-20T00:00:00+00:00' AIRFLOW_CTX_TRY_NUMBER='1' AIRFLOW_CTX_DAG_RUN_ID='scheduled__2022-12-20T00:00:00+00:00'
[2023-05-09T12:19:17.269+0000] {sql.py:262} INFO - Executing: create table if not exists record( execution_time timestamp)
[2023-05-09T12:19:17.291+0000] {taskinstance.py:1847} ERROR - Task failed with exception
Traceback (most recent call last):
  File "/home/airflow/.local/lib/python3.7/site-packages/airflow/providers/common/sql/operators/sql.py", line 263, in execute
    hook = self.get_db_hook()
  File "/home/airflow/.local/lib/python3.7/site-packages/airflow/providers/common/sql/operators/sql.py", line 181, in get_db_hook
    return self._hook
  File "/home/airflow/.local/lib/python3.7/site-packages/cached_property.py", line 36, in __get__
    value = obj.__dict__[self.func.__name__] = self.func(obj)
  File "/home/airflow/.local/lib/python3.7/site-packages/airflow/providers/common/sql/operators/sql.py", line 143, in _hook
    conn = BaseHook.get_connection(self.conn_id)
  File "/home/airflow/.local/lib/python3.7/site-packages/airflow/hooks/base.py", line 72, in get_connection
    conn = Connection.get_connection_from_secrets(conn_id)
  File "/home/airflow/.local/lib/python3.7/site-packages/airflow/models/connection.py", line 434, in get_connection_from_secrets
    raise AirflowNotFoundException(f"The conn_id `{conn_id}` isn't defined")
airflow.exceptions.AirflowNotFoundException: The conn_id `my_postgres_connection` isn't defined
[2023-05-09T12:19:17.294+0000] {taskinstance.py:1373} INFO - Marking task as FAILED. dag_id=question1, task_id=create_table, execution_date=20221220T000000, start_date=20230509T121917, end_date=20230509T121917
[2023-05-09T12:19:17.306+0000] {standard_task_runner.py:109} ERROR - Failed to execute job 357 for task create_table (The conn_id `my_postgres_connection` isn't defined; 1079)
[2023-05-09T12:19:17.334+0000] {local_task_job_runner.py:232} INFO - Task exited with return code 1
[2023-05-09T12:19:17.358+0000] {taskinstance.py:2674} INFO - 0 downstream tasks scheduled from follow-on schedule check
