[2023-05-11T15:30:28.134+0000] {taskinstance.py:1125} INFO - Dependencies all met for dep_context=non-requeueable deps ti=<TaskInstance: third_dag.dummy_task manual__2023-05-11T15:30:27.347034+00:00 [queued]>
[2023-05-11T15:30:28.148+0000] {taskinstance.py:1125} INFO - Dependencies all met for dep_context=requeueable deps ti=<TaskInstance: third_dag.dummy_task manual__2023-05-11T15:30:27.347034+00:00 [queued]>
[2023-05-11T15:30:28.148+0000] {taskinstance.py:1331} INFO - Starting attempt 1 of 1
[2023-05-11T15:30:28.162+0000] {taskinstance.py:1350} INFO - Executing <Task(PythonOperator): dummy_task> on 2023-05-11 15:30:27.347034+00:00
[2023-05-11T15:30:28.167+0000] {standard_task_runner.py:57} INFO - Started process 101 to run task
[2023-05-11T15:30:28.173+0000] {standard_task_runner.py:84} INFO - Running: ['***', 'tasks', 'run', 'third_dag', 'dummy_task', 'manual__2023-05-11T15:30:27.347034+00:00', '--job-id', '532', '--raw', '--subdir', 'DAGS_FOLDER/dag3.py', '--cfg-path', '/tmp/tmp5r1cr7_m']
[2023-05-11T15:30:28.175+0000] {standard_task_runner.py:85} INFO - Job 532: Subtask dummy_task
[2023-05-11T15:30:28.230+0000] {task_command.py:410} INFO - Running <TaskInstance: third_dag.dummy_task manual__2023-05-11T15:30:27.347034+00:00 [running]> on host 53a973574ead
[2023-05-11T15:30:28.313+0000] {taskinstance.py:1570} INFO - Exporting env vars: AIRFLOW_CTX_DAG_OWNER='***' AIRFLOW_CTX_DAG_ID='third_dag' AIRFLOW_CTX_TASK_ID='dummy_task' AIRFLOW_CTX_EXECUTION_DATE='2023-05-11T15:30:27.347034+00:00' AIRFLOW_CTX_TRY_NUMBER='1' AIRFLOW_CTX_DAG_RUN_ID='manual__2023-05-11T15:30:27.347034+00:00'
[2023-05-11T15:30:28.314+0000] {taskinstance.py:1847} ERROR - Task failed with exception
Traceback (most recent call last):
  File "/home/airflow/.local/lib/python3.7/site-packages/airflow/operators/python.py", line 181, in execute
    return_value = self.execute_callable()
  File "/home/airflow/.local/lib/python3.7/site-packages/airflow/operators/python.py", line 198, in execute_callable
    return self.python_callable(*self.op_args, **self.op_kwargs)
  File "/opt/airflow/dags/dag3.py", line 7, in _random_fail
    random_number = random.randint(1, 100)
NameError: name 'random' is not defined
[2023-05-11T15:30:28.324+0000] {taskinstance.py:1373} INFO - Marking task as FAILED. dag_id=third_dag, task_id=dummy_task, execution_date=20230511T153027, start_date=20230511T153028, end_date=20230511T153028
[2023-05-11T15:30:28.331+0000] {standard_task_runner.py:109} ERROR - Failed to execute job 532 for task dummy_task (name 'random' is not defined; 101)
[2023-05-11T15:30:28.346+0000] {local_task_job_runner.py:232} INFO - Task exited with return code 1
[2023-05-11T15:30:28.368+0000] {taskinstance.py:2674} INFO - 1 downstream tasks scheduled from follow-on schedule check
